Workbook

Sheet 使い方
B1: 『終末のサンクチュアリ』制作シート
B2: 物語の設定、あらすじ、字コンテを、このファイル1つで管理する(2026-10-25、ユーザーの指示)。小説は、このファイルのあとに書く。
B3: 青字の数字は入力(変えてよい)。そのほかは式か、書き込む内容。
B4: 設定(目安) | C4: 文字数 | D4: 出どころ
B5: 導入の目安 | C5: 500 | D5: 参考PDF「500文字以内」
B6: 山場1の目安 | C6: 1000 | D6: 参考PDF「1000文字以内」
B7: 山場2の目安 | C7: 1000 | D7: 参考PDF「1000文字以内」
B8: ヒキの目安 | C8: 500 | D8: 参考PDF「500文字以内」
B9: 字コンテ1話の合計(下限) | C9: 2000 | D9: 参考PDF「2〜3000文字程度」
B10: 字コンテ1話の合計(上限) | C10: 3000 | D10: 参考PDF「2〜3000文字程度」
B11: 各話あらすじの目安 | C11: 500 | D11: 2つ目の参考PDF(約500字)
B12: 全体あらすじの上限 | C12: 1500 | D12: CLAUDE.md「長くても1,500字まで」
B14: 制作のルーティン
B15: 1 設定(キャラ設定・世界観) | C15: 物語に必要な設定の正本。ここに書いたことだけを使う。足したいときは、先にチャットで提案して、許可をもらう | D15: 「キャラ設定」「世界観」
B16: 2 全体あらすじ | C16: 世界の状況 → 主人公 → 目的の順に、何も知らない人が読んで分かるように書く。1,500字まで | D16: 「全体あらすじ」
B17: 3 各話あらすじ | C17: 各話、約500字。「やりたいこと」と、1導入・2山場1・3山場2・4ヒキ | D17: 「各話あらすじ」
B18: 4 字コンテ | C18: セリフとト書きを1行ずつ書く。1話2,000〜3,000字。赤字・青字の指定つき | D18: 「字コンテ_○話」
B19: 5 小説に書き起こす | C19: 字コンテの出来事と台詞から外れない。外れたいときは、先に字コンテを直す | D19: novels/ の本文
C20: どの段階も、ユーザーのOKが出てから次へ進む。前の段階を直したら、あとの段階も合わせて直す。
B22: 参考PDFの分析 | C22: 内容 | D22: 確かさ
B23: 字コンテとは | C23: ネーム・作画担当さま向けの、1話ぶんのシナリオ設計シート。セリフとト書きを1行ずつ書く。見出しは、サブタイトルと、話の目的/見せたいもの | D23: 推測
B24: 列と構成 | C24: A文字数/B話者/Cシナリオ内容/Dキャラ情報/E心情・表情・演出プラン/F備考。導入・山場1・山場2・ヒキの4ブロックで、ブロックごとに小計(例:548+681+437+332=1998字、セリフ54) | D24: 確認
B25: 色 | C25: 赤字=魅せゴマ・キメ台詞(各ブロックに1つ以上)/青字=一番の見せ場(1つ)/ピンク字=強調(用途の説明なし) | D25: 赤・青は確認
B26: 心情 | C26: 目に見えないものは、セリフと演技で表す | D26: 確認
B27: 各話あらすじ | C27: 「やりたいこと」1〜2行+1〜4の番号つき4項目(4はヒキ)で約500字。前の話を指す書き方と、要の台詞の引用がある | D27: 確認
B29: 提出前の自己点検
C30: 字コンテ: 合計が目安の範囲か/赤字が導入・山場・ヒキに1つ以上あるか/青字が1つか/ミナの台詞に数字がないか
C31: 全話共通: 確定事項と衝突していないか(CLAUDE.md)/設定にないことを足していないか/読者が予想する展開10個を出して避けたか
C32: 色: 赤=魅せゴマ・キメ台詞、青=一番の見せ場。E列の「★」で始まる行はピンクで出る(強調したい表情・演出)

Sheet キャラ設定
A1: キャラ設定(正本)
A2: CLAUDE.mdの確定事項から転記。ここに無いことは足さない。足したいときは、先にチャットで提案する。
A4: 名前 | B4: 役割 | C4: 見た目 | D4: 性格・行動原理 | E4: 口調・台詞 | F4: やらないこと・禁止 | G4: 呼び方 | H4: 出どころ
A5: ミナ(水守ミナ) | B5: 主人公。19歳。地下の浄水施設で水質を管理してきた一族の娘 | C5: 身長162cm、細身。青白い肌。地上に出て首筋が赤く日焼けしている。手は冷水で赤く悴み、爪は深爪ぎりぎりで土汚れがない。煮沸した綿布と乾いた灰のにおい。腰に水質計測具を吊るす | D5: 感情の起伏が極端に薄い(低体温・マイペース)。怯えない。刃物を向けられても「危ないですよ」と平熱で返す。体は華奢で、小突かれたら死ぬ。自分を大切にする発想がなく、自分の水を平気でゼロにする。核は、腐敗や不衛生を放置するのが許せない職人の感覚(生活を回復させたい) | E5: 敬体・短文・平熱。怒鳴らない、取り乱さない、媚びない。決め台詞:「その手で、私に触らないでください」「わざわざ、痛い思いをしないでください」「まず、人間に戻りましょう」「洗えば、戻ります」「手入れのできない人は、嫌いです」 | F5: 怯えて口を塞ぐ、腰を抜かす/「怖い」「愛しい」などの感傷的な独白/台詞に数字を入れない(日数や水量はロクゾウ) | G5: ヨシノ→ミナ:お嬢様 ロクゾウ→ミナ:お嬢さん(のちに姐さん) | H5: 2026-10-25 最終仕様
A6: ハル | B6: ヒーロー。略奪団のボス | C6: 王子様のような美青年。髪は洗えば淡い金。灰青の切れ長の目。ただし野獣感は残す。左肩に傷 | D6: 地上でただ一人、ものすごく賢い切れ者。弱みを隠していたから、傷で死にかけた(弱ったボスは手下に寝首をかかれる)。暴力で世界を支配してきたので、命乞いする人と敵しか知らない。怯えず、媚びず、自分を消毒して飯を食わせるミナに、異常な過保護になる。早い段階でミナを選び、はっきり溺愛する | E6: 無口にしない。「口が悪い・声が大きい・俺の嫁だ」型のテンプレにしない。宣言は「お前を、妻にする」。意味は説明しない。話の要所の台詞はハルが言う | F6: 「番」は使わない。花嫁衣装を黙って差し出す場面はやめた。「名前がない」「番号で呼ばれて育った」設定はやめた | G6: 「ハルヴァルド・オルセン」の名は残す(「ハル」との関係は未決) | H6: CLAUDE.md 確定
A7: ヨシノ | B7: ミナの従者。女性 | C7: (未設定) | D7: 腕が立つ。怒りの起点は「ミナが自分を粗末にしていること」だけ。トピックを飛ばさせない | E7: ミナには敬語。「お嬢様」と呼ぶ | F7: 怒りの起点を増やさない | G7: ヨシノ→ミナ:お嬢様 | H7: CLAUDE.md 確定
A8: ロクゾウ | B8: ハルの右腕(手下)。痩せた男 | C8: 痩せている。指を折って数える | D8: 数えないと眠れない。ロクゾウだけが数字を口にする。ハルの手下の中では、現実的で損得を見る | E8: くだけた口調。「お嬢さん方」「姐さん」 | F8: 要所を持っていかせない | G8: ロクゾウ→ミナ:お嬢さん方(1話)/姐さん(8話ごろ) | H8: CLAUDE.md 確定(一部は旧あらすじ)
A9: イオリ | B9: ミナの婚約者。町を襲わせた人物 | C9: (未設定。1話では描かない) | D9: 小物のヒール。町を襲わせた理由は、しょぼくて胸くそ悪いもの(馬鹿にされた、皆に笑われたのが悔しかった、など)。地上に出た理由は未決(町でしてはいけないことをして、罪から逃げる方向) | E9: (未設定) | F9: 第1話ではイオリを描かない。町を襲わせたとミナが知るのは、再会のとき、本人の口から | G9: ミナ→イオリ:あなた | H9: CLAUDE.md 確定
A10: ゴロウ | B10: 荒野の別の略奪団の頭。敵 | C10: (未設定) | D10: ハルが子どものころ缶詰を奪われた男(旧あらすじより)。ミナの水を欲しがる | E10: (未設定) | F10: (未設定) | G10: (未設定) | H10: 仮置き(旧あらすじ第9稿)
A11: 叔父 | B11: ミナの叔父。1話のみ | C11: 袖口に継ぎ当てのある上着。目尻に皺 | D11: ミナを笑わせて帰る。夜、通路で死体になっている | E11: くだけた口調 | F11: (なし) | G11: (なし) | H11: 1話の本文

Sheet 世界観
A1: 世界観(正本)
A2: CLAUDE.mdの確定事項から転記。ここに無いことは足さない。
A4: 項目 | B4: 内容 | C4: 確かさ
A5: 舞台 | B5: 300年後の日本。国名・地名は出さない。地上は人種が混ざっている(理由は未決) | C5: 確定
A6: 地下の町 | B6: 300年間、誰も地上に出ていない。町は、みんなの飲み水を守る家(ミナの家)が水を調べている | C6: 確定
A7: 町の掟 | B7: 外では人は生きられない。扉は開けてはならない。だから300年、誰も外に出なかった | C7: 確定(2026-10-06)
A8: 町の滅亡 | B8: 出口を開けたのはイオリ(時期は最近。日数は未決)。地上の人間たちに襲われ、人々はほとんど殺される。町は滅んだままでよい。町に生き残った人はいない | C8: 確定
A9: 地上 | B9: 乾いた荒野。未知数。1話の空は、澄んだ夜明け | C9: 確定
A10: 町の跡 | B10: 領地を広げる途中で、見に行くパートがある(48話)。取りに行くものはなし | C10: 確定
A11: 契約(縛り) | B11: ミナの条件:自分のいる場所では誰も殺さない(理由は、水が汚れるから)。期限:イオリが見つかるまで。ハルは探すのを手伝い、ミナは水を作る。ミナは「妻」を契約上の呼び名と受け取る。契約の印は手当て | C11: 確定(2026-10-25)
A12: 契約の終わり(ラスト) | B12: 契約の期限は、再会(62話)の日に終わっていた。ミナはラストで気づく。気づかなかった理由は、契約の目的が済んだから(仮置き) | C12: 仮置き
A13: 外に出たあと | B13: 領地経営の物語。人が集まり、領地が広がる。たまに外から襲われ、こちらから広げにも行く。重い話にしない | C13: 確定(2026-10-09)
A14: 型 | B14: 1〜15話は必中型の骨格(訳アリの縛り、当て馬、じれ溺愛)。16話以降は領地経営のループ。100話は維持 | C14: 確定(2026-10-25)
A15: 連載先と文体 | B15: 小説版はなろう連載。台詞稿はやめ、普通の小説の文章で書く。1話の視点は、ミナ視点(三人称限定)。一人称への書き直しは検討中 | C15: 確定/検討中
... A17: 言葉の使い方 | B17: ミナの台詞に数字を入れない。作中の俗語(「野良」など)は使わない。「番」は使わない | C17: 確定

Sheet 全体あらすじ
A1: 全体あらすじ(第11稿・未承認)
A2: ミナの最終仕様(怯えない)に合わせて、第10稿から直した。出来事だけ。台詞は確定したものだけ。
A4: 文明が滅んで三百年。地上は乾いた荒野になり、人々の一部は、地下の町に逃げこんで暮らしてきた。町には掟がある。外では人は生きられない。だから出口の扉は開けてはならない。三百年のあいだ、誰も外に出なかった。 | B4: 字数
A5: ミナ(十九歳)は、その町で、みんなの飲み水を守ってきた家の娘。感情の起伏が薄く、何があっても怯えない。汚れた水やけがを見ると、考えるより先に手が動く。町の決めた婚約者イオリとの婚礼を控えた、最後の朝だった。 | B5: =SUMPRODUCT(LEN(A4:A11))&"字"
A6: その夜、開くはずのない扉が開き、地上の略奪者が町になだれこむ。町の人はほとんど殺される。ミナは従者のヨシノに手を引かれて地上へ逃げるが、荒野で盗賊に囲まれ、売り物として値踏みされる。そこへ王子様のように美しい青年が現れ、盗賊を追い払う。彼こそ荒野で恐れられる略奪団のボス、この物語のヒーローのハルだった。助けたのではなく、自分たちの売り物にするためだった。その汚れた手が伸びたとき、ミナは平熱のまま言う。「その手で、私に触らないでください」。ハルは怒らず、手を引く。 | B6: ="上限 "&使い方!$C$12&"字"&IF(SUMPRODUCT(LEN(A4:A11))>使い方!$C$12,"(超過)","(範囲内)")
A7: ハルは荒野一の切れ者なのに、弱いところを見せまいと傷を隠し、死にかけていた。ミナが傷を洗って命を救うと、ハルは言う。「お前を、妻にする」。意味の説明はない。ミナは、イオリが生きているのかを確かめたい。ハルは、探すのを手伝う代わりに、ミナに水を作らせる。ミナが出した条件は、自分のいる場所では誰も殺さないこと。期限は、イオリが見つかるまで。ミナは「妻」を、契約上の呼び名だと受け取る。
A8: ミナは、傷を腐らせていた薬を捨てさせ、水をきれいにし、手下たちに水を飲ませていく。ハルは何にでも「なぜだ」と聞き、ミナに手を洗われる。そこへ、荒野の別の略奪団の頭、ゴロウの使いが現れ、水場を寄こせと迫る。ミナは使いの水の悪さを言い当てる。続いて、偵察が置いていった手紙が届く。署名はイオリ。居場所はなく、迎えをやる、とだけ。ミナは本人のものか確信が持てず、隠したまま水を汲む。ハルは紙を見ず、ミナの顔色だけを察して席を外す。ゴロウの一団が迫る夜、ミナは水の危険を見抜いてハルの作戦を直し、一団は退く。
A9: ここから先は領地の物語になる。水を求めて人が集まり、領地は広がり、ミナはトマトを育てる。ときどき外から襲われ、こちらから広げにも行く。町の跡を見に行った日、生き残った人は一人もいなかった。ハルは、肩を切られた夜に自分から傷を見せに来て、初めてミナの名を呼ぶ。
A10: ミナは自分で決めて、イオリに会いに行く。町を襲わせたのは、彼だった。本人が、そう言った。皆に笑われたのが悔しかった、という子どもじみた理由だった。イオリはゴロウに切り捨てられ、ゴロウは領地の集落を取り上げ、ミナをさらう。閉じこめられた先でも、ミナは汚れた水をきれいにし、けが人を洗う。ゴロウの手下が、少しずつミナの側につく。ハルは作戦を立てて乗りこみ、ミナは最後に自分で決める。
A11: そのあと、ハルの右腕ロクゾウが何気なく日数を数えて口にする。イオリと会った日から、もう何日も経っている。ミナは遅れて気づく。契約の期限は、再会の日に終わっていた。ハルは、期限が過ぎても言い出さなかった。ミナは、泥だらけのハルの手を、洗わずに握る。翌朝、水場で水を小瓶に汲み、灯りにかざす。「澄んでいます。明日も、使えます」。昨日と同じ明日を、ミナは今日、自分で選んでいる。

Sheet 各話あらすじ
A1: 各話あらすじ(約500字)
A2: 書き方: 「やりたいこと」を1〜2行。そのあと、1導入・2山場1・3山場2・4ヒキの4項目。台詞は、要になる確定した台詞だけ。
A4: 話 | B4: サブタイトル | C4: やりたいこと | D4: 1 導入 | E4: 2 山場1 | F4: 3 山場2 | G4: 4 (ヒキ) | H4: 字数 | I4: 目安との差
A5: 1話 | B5: その手で、触らないでください | C5: 町の最後の朝から、町の滅亡、ハルとの出会いまで。優しい顔で近づいてきた最強の男に、ミナが平熱で「触らないでください」と言い、その手を止めさせる。ミナが怯えない人であることと、水と傷だけは見逃さないことを、1話で見せる。 | D5: 町の最後の朝。ミナは水を調べ、濁りがないのを確かめる。叔父に痩せたと言われ、水を見ていると食事を忘れる、と答えて笑われる。夜、悲鳴が上がり、ヨシノに連れられて地上へ逃げる。通路で、昼に笑っていた叔父の死体につまずき、ミナは声が出ず、足が止まる。 | E5: 階段を上ると、空に天井がない。盗賊に囲まれて値踏みされ、ミナは盗賊の水袋が腐っていることのほうが気になる。ヨシノが侮られると、ミナは自分を差し出して、ヨシノを離させようとする。ヨシノは「ご自分を、安く言わないでください」と怒り、殴りかかって、二人とも縛られる。 | F5: 盗賊の手首があらぬ向きに折れ、ハルが現れる。穏やかな声でミナの縄をほどくが、ミナは外套の下の、膿んだ傷のにおいに気づく。直後、ハルは「縛り直せ」と命じる。助けたのではなく、売り物にするためだった。ミナは、助けてくださったのではないのですね、と確かめるだけだった。 | G5: ハルが膝をつき、ミナの頬に手を伸ばす。爪の間が黒く、割れた爪の下に乾いていない血がある。ミナは「その手で、私に触らないでください」と言う。ロクゾウが「……終わった」とつぶやく。ハルは怒らず、手を引く。 | H5: =LEN(C5)+LEN(D5)+LEN(E5)+LEN(F5)+LEN(G5) | I5: =TEXT(H5-使い方!$C$11,"+0;-0;0")&"字"
A6: 2話 | B6: 洗わないと死にますよ | C6: ミナがハルの傷を洗って命を救い、ハルがミナを妻にすると決める。ミナが初めて、専門の手で人を救う。ハルは、怯えも媚びもしないミナに、これまで会ったことのない相手として、目を離せなくなる。 | D6: 朝、縛られたミナとヨシノが、ハルの前に座らされる。ハルは、なぜ触るなと言ったのかを聞く。答えるまでは殺さない、と言う。ミナは、ハルが左肩をかばう歩き方と、外套の下のにおいを、1話からずっと見ていた。 | E6: ミナは平熱のまま、「その傷、洗わないと死にますよ」と言う。ハルの顔から色が抜け、「見るな」と言う。弱みを見せれば、手下に寝首をかかれるからだ。ハルは手下とヨシノを外へ出し、ミナだけを残し、ミナの縄を切る。手が使えなければ、洗えない。 | F6: ミナが傷を洗う。皮を剥がして膿を出し、お湯をかけて流す。ハルは声を出さずに耐える。1話で「触らないで」と言った手が、今度は自分から、ハルの傷に触れる。ハルは、ミナの指先が驚くほど冷たいことに気づく。血の色がきれいになったら、洗い終わり。 | G6: ハルは、借りができたと言い、「お前を、妻にする」と宣言する。意味の説明はない。ミナには、言葉の意味は分かるが、なぜ自分にそう言うのかが分からない。 | H6: =LEN(C6)+LEN(D6)+LEN(E6)+LEN(F6)+LEN(G6) | I6: =TEXT(H6-使い方!$C$11,"+0;-0;0")&"字"
A7: 3話 | B7: 条件が、あります | C7: ミナが自分から条件を出して、ハルと契約する。契約の印は、握手ではなく手当てになる。この契約が、100話を通じた物語の縛りになる。ミナは取引のつもりで、ハルは、取引ではないと訂正しない。 | D7: 一夜。ミナは「妻」の意味が分からないまま、夜を過ごす。ヨシノは、略奪者から逃げようと言う。ミナは、逃げても帰る町がないこと、婚約者のイオリが生きているのかを確かめたいことを、淡々と話す。ヨシノは、ミナの言い方が、自分を勘定に入れていないことに怒る。 | E7: ミナはハルに、イオリが生きているのかを確かめたい、と話す。ハルは、探すのを手伝う代わりに、ミナに水を作らせる、と言う。ミナは、取引だと理解する。ハルが妻と呼ぶのは、取引の相手の呼び名だと受け取る。水を作ることで、ここにいる代金を払うつもりでいる。 | F7: ミナが条件を出す。自分のいる場所では、誰も殺さない。理由は、水が汚れるから。期限は、イオリが見つかるまで。ハルは一瞬黙る。ミナは気づかない。読者だけが、その沈黙に気づく。 | G7: ヨシノの縄が切られる。ミナは、握手の代わりに、ハルの傷の続きを診ます、と言う。契約の印は、手当てになる。 | H7: =LEN(C7)+LEN(D7)+LEN(E7)+LEN(F7)+LEN(G7) | I7: =TEXT(H7-使い方!$C$11,"+0;-0;0")&"字"
A8: 最終話(仮) | B8: (仮題なし) | C8: 契約の期限がとうに過ぎていたことが分かり、ミナがハルの泥の手を、洗わずに握る。1話の朝を、もう一度見せる。契約が終わったあとも、ミナが自分で選んで、ここにいることを見せる。 | D8: 夕方、作業を終えた水場で、ロクゾウが数える癖で、何気なく、イオリと会った日からの日数を口にする。ヨシノは黙って目をそらす。ヨシノは、ずっと気づいていたが、ミナには黙っていた。 | E8: ミナだけが、遅れて気づく。契約の期限は、イオリと再会した日に終わっていた。イオリは、ミナにとって、もう探す相手ではなくなっていた。だから、確かめたいことが済んだあとも、期限のことを考えなかった。ハルは、期限が過ぎても、言い出さなかった。 | F8: ハルは、泥だらけの手のまま、何も言わず立っている。ミナは、水と衛生の専門家として、洗わせるはずの手を、洗わずに握る。1話で「触らないで」と言った手を、専門の反射ではなく、自分の意思で握る。 | G8: 翌朝、水場。ミナは水を小瓶に汲み、灯りにかざす。濁りはない。昨日と同じ。「澄んでいます。明日も、使えます」。昨日と同じ明日を、ミナは今日、自分で選んでいる。1話の朝と同じ水場で終わる。 | H8: =LEN(C8)+LEN(D8)+LEN(E8)+LEN(F8)+LEN(G8) | I8: =TEXT(H8-使い方!$C$11,"+0;-0;0")&"字"

Sheet 字コンテ_1話
A1: サブタイトル | B1: その手で、触らないでください
A2: 話の目的／ 見せたいもの | B2: 町が滅び、ハルに出会う。ハルが優しい顔で手を伸ばしたとき、ミナが平熱で「触らないで」と言って、最強の男を止める。(仮置き: 叔父の死のあと、ミナは感情が切れたように平熱になる)
A4: ="文字数"&CHAR(10)&(A5+A21+A50+A69) | B4: ="セリフ数:"&CHAR(10)&COUNTIF(C6:C80,"「*") | C4: シナリオ内容(2〜3000文字程度) ※赤字=魅せゴマ・キメ台詞(導入・山場・ヒキに各1つ以上) ※青字=この話で一番の見せ場(1つ) ※心情は、台詞と演技で書く | D4: キャラ情報 場所・時間・背景など ※場面が変わるときに書く | E4: 心情・表情・演出プラン ※台詞とト書きで描き切れない心情や演出があれば | F4: その他備考 ※補足、イメージなど
A5: =SUM(A6:A20) | B5: 導入 | C5: ="※"&使い方!$C$5&"文字以内" | E5: ="目安との差 "&TEXT(A5-使い方!$C$5,"+0;-0;0")&"字"
A6: =IF(C6="","",LEN(C6)) | C6: 水場に並ぶ町の人たち。ミナ、桶の水を小瓶に汲み、灯りにかざす。濁りはない。昨日と同じ。 | D6: 地下の町・水場。昼も夜も同じ黄色い灯り。最後の朝。 ミナ:作業用の前掛け。腰に水質計測具 | E6: ★無表情。目は水だけを見ている | F6: ミナは怯えない人。感情は動かず、手と目で仕事をする
A7: =IF(C7="","",LEN(C7)) | B7: 叔父 | C7: 「痩せたな。式の前に倒れるなよ」 | D7: 叔父:袖口に継ぎ当てのある上着。目尻に皺 | F7: 婚礼の衣の寸法合わせのこと
A8: =IF(C8="","",LEN(C8)) | B8: ミナ | C8: 「水を見ていると、食事を忘れるので」 | E8: 冗談のつもりはない。平熱
A9: =IF(C9="","",LEN(C9)) | C9: 叔父、噴き出し、桶を揺らして帰っていく。 | F9: 叔父の笑顔を、読者に覚えさせる
A10: =IF(C10="","",LEN(C10)) | B10: 字幕 | C10: 広間の奥に、閉じたままの分厚い扉。外では人は生きられない。扉は開けてはならない。三百年、誰も触れていない。 | F10: 掟の説明は、ここ一度だけ
A11: =IF(C11="","",LEN(C11)) | C11: 夜。眠りかけたミナの耳に、階段の上から悲鳴が届く。二つ、三つ。悲鳴は重なり、床を伝って降りてくる。焦げたにおい。腹に響く重い軋み。 | D11: 夜。ミナの部屋
A12: =IF(C12="","",LEN(C12)) | B12: ミナ | C12: 「悲鳴が、増えています」 | E12: ★起き上がるが、慌てない
A13: =IF(C13="","",LEN(C13)) | C13: 戸が乱暴に開き、ヨシノが飛びこんでくる。髪が乱れ、肩で息をしている。 | D13: ヨシノ:髪が乱れ、息が荒い
A14: =IF(C14="","",LEN(C14)) | B14: ヨシノ | C14: 「お嬢様、立ってください。ここにいたら殺されます。地上に出ます」
A15: =IF(C15="","",LEN(C15)) | B15: ミナ | C15: 「地上に出ると、死にます」 | E15: ★言い方は平熱。事実を確認しているだけ
A16: =IF(C16="","",LEN(C16)) | B16: ヨシノ | C16: 「ここにいても死にます」
A17: =IF(C17="","",LEN(C17)) | C17: 通路。半分消えた灯り。ミナ、何かにつまずく。叔父の腕。袖口に継ぎ当て。目を開けたまま、こちらを向いた顔。 | D17: 町の通路(夜) | E17: ★足が止まる。声が出ない | F17: 叔父の死体(魅せゴマ)。感情は、体で見せる
A18: =IF(C18="","",LEN(C18)) | C18: ヨシノが脇に手を入れて引き起こす。叔父の顔は、もう見えない。
A19: =IF(C19="","",LEN(C19)) | C19: 広間の灯りが、一瞬揺れる。三百年同じだった黄色が、赤に変わっていく。 | F19: 灯りの色が、町の終わりを知らせる
A20: =IF(C20="","",LEN(C20)) | C20: 広間。人の声がひとつもしない。奥の扉が開き、薄青い光が床に四角く落ちる。鉄の切れ端を巻いた男たちが、前だけを見て町の奥へ走っていく。 | D20: 広間。奥に開いた扉 | F20: 壁際を駆ける二人には、目もくれない
A21: =SUM(A22:A49) | B21: 山場1 | C21: ="※"&使い方!$C$6&"文字以内" | E21: ="目安との差 "&TEXT(A21-使い方!$C$6,"+0;-0;0")&"字"
A22: =IF(C22="","",LEN(C22)) | C22: 扉の先は、手すりのない急な階段。ミナ、一段目に足をかけて止まる。
A23: =IF(C23="","",LEN(C23)) | B23: ミナ | C23: 「掟では、外では息ができません」
A24: =IF(C24="","",LEN(C24)) | B24: ヨシノ | C24: 「お嬢様」 | E24: 手を握ったまま、離さない
A25: =IF(C25="","",LEN(C25)) | C25: 上る背中に、下から名前を呼ぶ声が追ってくる。同じ名を三度。四度目はない。広間の灯りに、赤い色が混じる。
A26: =IF(C26="","",LEN(C26)) | C26: 最後の段の前で、ミナは息を止める。胸が痛くなるまでこらえ、吐いて、吸う。
A27: =IF(C27="","",LEN(C27)) | B27: ミナ | C27: 「……吸えました」
A28: =IF(C28="","",LEN(C28)) | C28: 階段を上りきる。天井がない。東の端だけ橙の空。見ているあいだにも、色が変わっていく。 | D28: 地上・岩場。夜明け。 ミナ:寝間着。肩にヨシノが婚礼の衣を掛けている(仮置き) | E28: ★目が離れない。感情が切れたように、平熱 | F28: 叔父の死のあと、ミナの感情が止まる。ここから平熱(仮置きA)
A29: =IF(C29="","",LEN(C29)) | B29: ミナ | C29: 「……天井が、ありません」
A30: =IF(C30="","",LEN(C30)) | C30: ミナ、空から視線を戻し、後ろを振り返る。階段の穴から、赤い灯りが漏れている。 | E30: ★振り返るだけ。取り乱さない | F30: 町の人たちの死を、ここで一度だけ思い出させる
A31: =IF(C31="","",LEN(C31)) | C31: 岩陰から盗賊が四人。ミナとヨシノを取り囲む。
A32: =IF(C32="","",LEN(C32)) | B32: 髭の男 | C32: 「ほんとに穴から出てきやがった。肌がきれいだな」 | D32: 髭の男:腰に水袋
A33: =IF(C33="","",LEN(C33)) | B33: 盗賊 | C33: 「穴の中の連中は、みんなこんなに肌が白いのか。いい値がつくぞ」
A34: =IF(C34="","",LEN(C34)) | C34: 髭の男、ミナの顎をつかんで左右に向ける。ミナの目は、男の水袋に行く。 | E34: 水袋の口から、腐りかけた水のにおい
A35: =IF(C35="","",LEN(C35)) | B35: ミナ | C35: 「その水袋、腐っています」 | E35: 確認として言う。命乞いでも抗議でもない | F35: ミナは、状況より水を優先して見てしまう
A36: =IF(C36="","",LEN(C36)) | B36: 髭の男 | C36: 「あ?」
A37: =IF(C37="","",LEN(C37)) | B37: 盗賊 | C37: 「上物だ。売る前に味見くらいいいだろ」 | E37: 笑いが起きる。岩に寄りかかった男が一人、止めもせずにあくびをしている
A38: =IF(C38="","",LEN(C38)) | B38: ヨシノ | C38: 「お嬢様、私の後ろに」
A39: =IF(C39="","",LEN(C39)) | C39: 盗賊たち、笑いながら二人の周りを一周して、値踏みする。
A40: =IF(C40="","",LEN(C40)) | B40: ヨシノ | C40: 「手を放してください」
A41: =IF(C41="","",LEN(C41)) | B41: 盗賊 | C41: 「女の用心棒かよ。棒きれの腕で、何ができる」 | E41: ヨシノの袖をまくり上げる。ヨシノは唇を噛み、動かない
...

Sheet 字コンテ_テンプレート
A1: サブタイトル
A2: 話の目的／ 見せたいもの
A4: ="文字数"&CHAR(10)&(A5+A9+A13+A17) | B4: ="セリフ数:"&CHAR(10)&COUNTIF(C6:C20,"「*") | C4: シナリオ内容(2〜3000文字程度) ※赤字=魅せゴマ・キメ台詞(導入・山場・ヒキに各1つ以上) ※青字=この話で一番の見せ場(1つ) ※心情は、台詞と演技で書く | D4: キャラ情報 場所・時間・背景など ※場面が変わるときに書く | E4: 心情・表情・演出プラン ※台詞とト書きで描き切れない心情や演出があれば | F4: その他備考 ※補足、イメージなど
A5: =SUM(A6:A8) | B5: 導入 | C5: ="※"&使い方!$C$5&"文字以内" | E5: ="目安との差 "&TEXT(A5-使い方!$C$5,"+0;-0;0")&"字"
A6: =IF(C6="","",LEN(C6))
A7: =IF(C7="","",LEN(C7))
A8: =IF(C8="","",LEN(C8))
A9: =SUM(A10:A12) | B9: 山場1 | C9: ="※"&使い方!$C$6&"文字以内" | E9: ="目安との差 "&TEXT(A9-使い方!$C$6,"+0;-0;0")&"字"
A10: =IF(C10="","",LEN(C10))
A11: =IF(C11="","",LEN(C11))
A12: =IF(C12="","",LEN(C12))
A13: =SUM(A14:A16) | B13: 山場2 | C13: ="※"&使い方!$C$7&"文字以内" | E13: ="目安との差 "&TEXT(A13-使い方!$C$7,"+0;-0;0")&"字"
A14: =IF(C14="","",LEN(C14))
A15: =IF(C15="","",LEN(C15))
A16: =IF(C16="","",LEN(C16))
A17: =SUM(A18:A20) | B17: ヒキ | C17: ="※"&使い方!$C$8&"文字以内" | E17: ="目安との差 "&TEXT(A17-使い方!$C$8,"+0;-0;0")&"字"
A18: =IF(C18="","",LEN(C18))
A19: =IF(C19="","",LEN(C19))
A20: =IF(C20="","",LEN(C20))
B22: 合計 | C22: =(A5+A9+A13+A17)&"字(目安 "&使い方!$C$9&"〜"&使い方!$C$10&"字)"
